<?xml version='1.0'?>
<sdf version='1.6'>
  <model name='omni_car'>
    <link name='dummy'>
      <inertial>
        <pose frame=''>0.000456 0 0.000638 0 -0 0</pose>
        <mass>8.2301</mass>
        <inertia>
          <ixx>0.0209684</ixx>
          <ixy>0</ixy>
          <ixz>-0.000653858</ixz>
          <iyy>0.0214354</iyy>
          <iyz>0</iyz>
          <izz>0.02047</izz>
        </inertia>
      </inertial>
      <velocity_decay/>
      <velocity_decay/>
      <velocity_decay/>
      <velocity_decay/>
      <sensor name='camera1' type='camera'>
        <update_rate>30</update_rate>
        <camera name='head'>
          <horizontal_fov>1.39626</horizontal_fov>
          <image>
            <width>1920</width>
            <height>1080</height>
            <format>R8G8B8</format>
          </image>
          <clip>
            <near>0.02</near>
            <far>300</far>
          </clip>
          <noise>
            <type>gaussian</type>
            <mean>0</mean>
            <stddev>0.007</stddev>
          </noise>
        </camera>
        <plugin name='camera_controller' filename='libgazebo_ros_camera.so'>
          <alwaysOn>1</alwaysOn>
          <updateRate>0.0</updateRate>
          <cameraName>/</cameraName>
          <imageTopicName>cam</imageTopicName>
          <cameraInfoTopicName>camera_info</cameraInfoTopicName>
          <frameName>camera_link</frameName>
          <hackBaseline>0.07</hackBaseline>
          <distortionK1>0.0</distortionK1>
          <distortionK2>0.0</distortionK2>
          <distortionK3>0.0</distortionK3>
          <distortionT1>0.0</distortionT1>
          <distortionT2>0.0</distortionT2>
          <robotNamespace>/</robotNamespace>
        </plugin>
        <pose frame=''>0.125 0 0.175 0 -0 0</pose>
      </sensor>
      <velocity_decay/>
      <sensor name='head_hokuyo_sensor' type='ray'>
        <visualize>0</visualize>
        <update_rate>15</update_rate>
        <ray>
          <scan>
            <horizontal>
              <samples>720</samples>
              <resolution>1</resolution>
              <min_angle>-3.14159</min_angle>
              <max_angle>3.14159</max_angle>
            </horizontal>
            <vertical>
              <samples>1</samples>
              <min_angle>0</min_angle>
              <max_angle>0</max_angle>
            </vertical>
          </scan>
          <range>
            <min>0.05</min>
            <max>30</max>
            <resolution>0.01</resolution>
          </range>
          <noise>
            <type>gaussian</type>
            <mean>0</mean>
            <stddev>0.01</stddev>
          </noise>
        </ray>
        <plugin name='gazebo_ros_head_hokuyo_controller' filename='libgazebo_ros_laser.so'>
          <topicName>/scan</topicName>
          <frameName>laser_frame</frameName>
          <robotNamespace>/</robotNamespace>
        </plugin>
        <pose frame=''>0.125 0 0.225 0 -0 0</pose>
      </sensor>
      <gravity>1</gravity>
      <velocity_decay/>
      <gravity>1</gravity>
      <sensor name='imu_sensor' type='imu'>
        <always_on>1</always_on>
        <update_rate>100</update_rate>
        <visualize>1</visualize>
        <topic>__default_topic__</topic>
        <plugin name='imu_plugin' filename='libgazebo_ros_imu_sensor.so'>
          <topicName>imu</topicName>
          <bodyName>imu_link</bodyName>
          <updateRateHZ>100.0</updateRateHZ>
          <gaussianNoise>0.0</gaussianNoise>
          <xyzOffset>0 0 0</xyzOffset>
          <rpyOffset>0 0 0</rpyOffset>
          <frameName>imu_link</frameName>
          <robotNamespace>/</robotNamespace>
        </plugin>
        <pose frame=''>0.125 0 0.125 0 -0 0</pose>
        <imu/>
      </sensor>
      <self_collide>0</self_collide>
      <enable_wind>0</enable_wind>
      <kinematic>0</kinematic>
      <pose frame=''>0 0 0 0 -0 0</pose>
      <visual name='dummy_fixed_joint_lump__base_footprint_visual'>
        <pose frame=''>0 0 0 0 -0 0</pose>
        <geometry>
          <box>
            <size>0.001 0.001 0.001</size>
          </box>
        </geometry>
        <material>
          <script>
            <name>Gazebo/Green</name>
            <uri>file://media/materials/scripts/gazebo.material</uri>
          </script>
          <shader type='pixel'/>
        </material>
        <transparency>0</transparency>
        <cast_shadows>1</cast_shadows>
      </visual>
      <visual name='dummy_fixed_joint_lump__base_link_visual_1'>
        <pose frame=''>0 0 0.05 0 -0 1.5708</pose>
        <geometry>
          <box>
            <size>0.2 0.3 0.1</size>
          </box>
        </geometry>
        <material>
          <script>
            <name>Gazebo/Orange</name>
            <uri>file://media/materials/scripts/gazebo.material</uri>
          </script>
          <shader type='pixel'/>
        </material>
        <transparency>0</transparency>
        <cast_shadows>1</cast_shadows>
      </visual>
      <visual name='dummy_fixed_joint_lump__camera_link_visual_2'>
        <pose frame=''>0.125 0 0.175 0 -0 0</pose>
        <geometry>
          <box>
            <size>0.05 0.05 0.05</size>
          </box>
        </geometry>
        <material>
          <script>
            <name>Gazebo/Red</name>
            <uri>file://media/materials/scripts/gazebo.material</uri>
          </script>
          <shader type='pixel'/>
        </material>
        <transparency>0</transparency>
        <cast_shadows>1</cast_shadows>
      </visual>
      <visual name='dummy_fixed_joint_lump__laser_frame_visual_3'>
        <pose frame=''>0.125 0 0.225 0 -0 0</pose>
        <geometry>
          <mesh>
            <scale>1 1 1</scale>
            <uri>/home/chh3213/ros_wc/src/gazebo_car/meshes/hokuyo.dae</uri>
          </mesh>
        </geometry>
        <material>
          <shader type='pixel'/>
        </material>
        <transparency>0</transparency>
        <cast_shadows>1</cast_shadows>
      </visual>
      <visual name='dummy_fixed_joint_lump__imu_link_visual_4'>
        <pose frame=''>0.125 0 0.125 0 -0 0</pose>
        <geometry>
          <box>
            <size>0.05 0.05 0.05</size>
          </box>
        </geometry>
        <material>
          <script>
            <name>Gazebo/Orange</name>
            <uri>file://media/materials/scripts/gazebo.material</uri>
          </script>
          <shader type='pixel'/>
        </material>
        <transparency>0</transparency>
        <cast_shadows>1</cast_shadows>
      </visual>
      <collision name='dummy_fixed_joint_lump__base_link_collision'>
        <laser_retro>0</laser_retro>
        <max_contacts>10</max_contacts>
        <pose frame=''>0 0 0 0 -0 0</pose>
        <geometry>
          <box>
            <size>0.2 0.3 0.1</size>
          </box>
        </geometry>
        <surface>
          <friction>
            <ode>
              <mu>1</mu>
              <mu2>1</mu2>
              <fdir1>0 0 0</fdir1>
              <slip1>0</slip1>
              <slip2>0</slip2>
            </ode>
            <torsional>
              <coefficient>1</coefficient>
              <patch_radius>0</patch_radius>
              <surface_radius>0</surface_radius>
              <use_patch_radius>1</use_patch_radius>
              <ode>
                <slip>0</slip>
              </ode>
            </torsional>
          </friction>
          <bounce>
            <restitution_coefficient>0</restitution_coefficient>
            <threshold>1e+06</threshold>
          </bounce>
          <contact>
            <collide_without_contact>0</collide_without_contact>
            <collide_without_contact_bitmask>1</collide_without_contact_bitmask>
            <collide_bitmask>1</collide_bitmask>
            <ode>
              <soft_cfm>0</soft_cfm>
              <soft_erp>0.2</soft_erp>
              <kp>1e+13</kp>
              <kd>1</kd>
              <max_vel>0.01</max_vel>
              <min_depth>0</min_depth>
            </ode>
            <bullet>
              <split_impulse>1</split_impulse>
              <split_impulse_penetration_threshold>-0.01</split_impulse_penetration_threshold>
              <soft_cfm>0</soft_cfm>
              <soft_erp>0.2</soft_erp>
              <kp>1e+13</kp>
              <kd>1</kd>
            </bullet>
          </contact>
        </surface>
      </collision>
      <collision name='dummy_fixed_joint_lump__camera_link_collision_1'>
        <laser_retro>0</laser_retro>
        <max_contacts>10</max_contacts>
        <pose frame=''>0.125 0 0.175 0 -0 0</pose>
        <geometry>
          <box>
            <size>0.05 0.05 0.05</size>
          </box>
        </geometry>
        <surface>
          <friction>
            <ode>
              <mu>1</mu>
              <mu2>1</mu2>
              <fdir1>0 0 0</fdir1>
              <slip1>0</slip1>
              <slip2>0</slip2>
            </ode>
            <torsional>
              <coefficient>1</coefficient>
              <patch_radius>0</patch_radius>
              <surface_radius>0</surface_radius>
              <use_patch_radius>1</use_patch_radius>
              <ode>
                <slip>0</slip>
              </ode>
            </torsional>
          </friction>
          <bounce>
            <restitution_coefficient>0</restitution_coefficient>
            <threshold>1e+06</threshold>
          </bounce>
          <contact>
            <collide_without_contact>0</collide_without_contact>
            <collide_without_contact_bitmask>1</collide_without_contact_bitmask>
            <collide_bitmask>1</collide_bitmask>
            <ode>
              <soft_cfm>0</soft_cfm>
              <soft_erp>0.2</soft_erp>
              <kp>1e+13</kp>
              <kd>1</kd>
              <max_vel>0.01</max_vel>
              <min_depth>0</min_depth>
            </ode>
            <bullet>
              <split_impulse>1</split_impulse>
              <split_impulse_penetration_threshold>-0.01</split_impulse_penetration_threshold>
              <soft_cfm>0</soft_cfm>
              <soft_erp>0.2</soft_erp>
              <kp>1e+13</kp>
              <kd>1</kd>
            </bullet>
          </contact>
        </surface>
      </collision>
      <collision name='dummy_fixed_joint_lump__imu_link_collision_3'>
        <laser_retro>0</laser_retro>
        <max_contacts>10</max_contacts>
        <pose frame=''>0.125 0 0.125 0 -0 0</pose>
        <geometry>
          <box>
            <size>0.05 0.05 0.05</size>
          </box>
        </geometry>
        <surface>
          <friction>
            <ode>
              <mu>1</mu>
              <mu2>1</mu2>
              <fdir1>0 0 0</fdir1>
              <slip1>0</slip1>
              <slip2>0</slip2>
            </ode>
            <torsional>
              <coefficient>1</coefficient>
              <patch_radius>0</patch_radius>
              <surface_radius>0</surface_radius>
              <use_patch_radius>1</use_patch_radius>
              <ode>
                <slip>0</slip>
              </ode>
            </torsional>
          </friction>
          <bounce>
            <restitution_coefficient>0</restitution_coefficient>
            <threshold>1e+06</threshold>
          </bounce>
          <contact>
            <collide_without_contact>0</collide_without_contact>
            <collide_without_contact_bitmask>1</collide_without_contact_bitmask>
            <collide_bitmask>1</collide_bitmask>
            <ode>
              <soft_cfm>0</soft_cfm>
              <soft_erp>0.2</soft_erp>
              <kp>1e+13</kp>
              <kd>1</kd>
              <max_vel>0.01</max_vel>
              <min_depth>0</min_depth>
            </ode>
            <bullet>
              <split_impulse>1</split_impulse>
              <split_impulse_penetration_threshold>-0.01</split_impulse_penetration_threshold>
              <soft_cfm>0</soft_cfm>
              <soft_erp>0.2</soft_erp>
              <kp>1e+13</kp>
              <kd>1</kd>
            </bullet>
          </contact>
        </surface>
      </collision>
      <collision name='dummy_fixed_joint_lump__laser_frame_collision_2'>
        <laser_retro>0</laser_retro>
        <max_contacts>10</max_contacts>
        <pose frame=''>0.125 0 0.225 0 -0 0</pose>
        <geometry>
          <box>
            <size>0.05 0.05 0.05</size>
          </box>
        </geometry>
        <surface>
          <friction>
            <ode>
              <mu>1</mu>
              <mu2>1</mu2>
              <fdir1>0 0 0</fdir1>
              <slip1>0</slip1>
              <slip2>0</slip2>
            </ode>
            <torsional>
              <coefficient>1</coefficient>
              <patch_radius>0</patch_radius>
              <surface_radius>0</surface_radius>
              <use_patch_radius>1</use_patch_radius>
              <ode>
                <slip>0</slip>
              </ode>
            </torsional>
          </friction>
          <bounce>
            <restitution_coefficient>0</restitution_coefficient>
            <threshold>1e+06</threshold>
          </bounce>
          <contact>
            <collide_without_contact>0</collide_without_contact>
            <collide_without_contact_bitmask>1</collide_without_contact_bitmask>
            <collide_bitmask>1</collide_bitmask>
            <ode>
              <soft_cfm>0</soft_cfm>
              <soft_erp>0.2</soft_erp>
              <kp>1e+13</kp>
              <kd>1</kd>
              <max_vel>0.01</max_vel>
              <min_depth>0</min_depth>
            </ode>
            <bullet>
              <split_impulse>1</split_impulse>
              <split_impulse_penetration_threshold>-0.01</split_impulse_penetration_threshold>
              <soft_cfm>0</soft_cfm>
              <soft_erp>0.2</soft_erp>
              <kp>1e+13</kp>
              <kd>1</kd>
            </bullet>
          </contact>
        </surface>
      </collision>
    </link>
    <link name='wheel_1'>
      <pose frame=''>0.099999 0.13 -0 -1.5708 0 0</pose>
      <inertial>
        <pose frame=''>0 0 0 0 -0 0</pose>
        <mass>0.5</mass>
        <inertia>
          <ixx>0.01</ixx>
          <ixy>0</ixy>
          <ixz>0</ixz>
          <iyy>0.01</iyy>
          <iyz>0</iyz>
          <izz>0.01</izz>
        </inertia>
      </inertial>
      <gravity>1</gravity>
      <velocity_decay/>
      <self_collide>0</self_collide>
      <enable_wind>0</enable_wind>
      <kinematic>0</kinematic>
      <visual name='wheel_1_visual'>
        <pose frame=''>0 0 0 0 -0 0</pose>
        <geometry>
          <cylinder>
            <length>0.05</length>
            <radius>0.06</radius>
          </cylinder>
        </geometry>
        <material>
          <script>
            <name>Gazebo/Red</name>
            <uri>file://media/materials/scripts/gazebo.material</uri>
          </script>
          <shader type='pixel'/>
        </material>
        <transparency>0</transparency>
        <cast_shadows>1</cast_shadows>
      </visual>
      <collision name='wheel_1_collision'>
        <laser_retro>0</laser_retro>
        <max_contacts>10</max_contacts>
        <pose frame=''>0 0 0 0 -0 0</pose>
        <geometry>
          <cylinder>
            <radius>0.06</radius>
            <length>0.05</length>
          </cylinder>
        </geometry>
        <surface>
          <friction>
            <ode>
              <mu>1</mu>
              <mu2>1</mu2>
              <fdir1>0 0 0</fdir1>
              <slip1>0</slip1>
              <slip2>0</slip2>
            </ode>
            <torsional>
              <coefficient>1</coefficient>
              <patch_radius>0</patch_radius>
              <surface_radius>0</surface_radius>
              <use_patch_radius>1</use_patch_radius>
              <ode>
                <slip>0</slip>
              </ode>
            </torsional>
          </friction>
          <bounce>
            <restitution_coefficient>0</restitution_coefficient>
            <threshold>1e+06</threshold>
          </bounce>
          <contact>
            <collide_without_contact>0</collide_without_contact>
            <collide_without_contact_bitmask>1</collide_without_contact_bitmask>
            <collide_bitmask>1</collide_bitmask>
            <ode>
              <soft_cfm>0</soft_cfm>
              <soft_erp>0.2</soft_erp>
              <kp>1e+13</kp>
              <kd>1</kd>
              <max_vel>0.01</max_vel>
              <min_depth>0</min_depth>
            </ode>
            <bullet>
              <split_impulse>1</split_impulse>
              <split_impulse_penetration_threshold>-0.01</split_impulse_penetration_threshold>
              <soft_cfm>0</soft_cfm>
              <soft_erp>0.2</soft_erp>
              <kp>1e+13</kp>
              <kd>1</kd>
            </bullet>
          </contact>
        </surface>
      </collision>
    </link>
    <link name='wheel_2'>
      <pose frame=''>-0.1 0.13 -0 -1.5708 0 0</pose>
      <inertial>
        <pose frame=''>0 0 0 0 -0 0</pose>
        <mass>0.5</mass>
        <inertia>
          <ixx>0.01</ixx>
          <ixy>0</ixy>
          <ixz>0</ixz>
          <iyy>0.01</iyy>
          <iyz>0</iyz>
          <izz>0.01</izz>
        </inertia>
      </inertial>
      <gravity>1</gravity>
      <velocity_decay/>
      <self_collide>0</self_collide>
      <enable_wind>0</enable_wind>
      <kinematic>0</kinematic>
      <visual name='wheel_2_visual'>
        <pose frame=''>0 0 0 0 -0 0</pose>
        <geometry>
          <cylinder>
            <length>0.05</length>
            <radius>0.06</radius>
          </cylinder>
        </geometry>
        <material>
          <script>
            <name>Gazebo/Black</name>
            <uri>file://media/materials/scripts/gazebo.material</uri>
          </script>
          <shader type='pixel'/>
        </material>
        <transparency>0</transparency>
        <cast_shadows>1</cast_shadows>
      </visual>
      <collision name='wheel_2_collision'>
        <laser_retro>0</laser_retro>
        <max_contacts>10</max_contacts>
        <pose frame=''>0 0 0 0 -0 0</pose>
        <geometry>
          <cylinder>
            <radius>0.06</radius>
            <length>0.05</length>
          </cylinder>
        </geometry>
        <surface>
          <friction>
            <ode>
              <mu>1</mu>
              <mu2>1</mu2>
              <fdir1>0 0 0</fdir1>
              <slip1>0</slip1>
              <slip2>0</slip2>
            </ode>
            <torsional>
              <coefficient>1</coefficient>
              <patch_radius>0</patch_radius>
              <surface_radius>0</surface_radius>
              <use_patch_radius>1</use_patch_radius>
              <ode>
                <slip>0</slip>
              </ode>
            </torsional>
          </friction>
          <bounce>
            <restitution_coefficient>0</restitution_coefficient>
            <threshold>1e+06</threshold>
          </bounce>
          <contact>
            <collide_without_contact>0</collide_without_contact>
            <collide_without_contact_bitmask>1</collide_without_contact_bitmask>
            <collide_bitmask>1</collide_bitmask>
            <ode>
              <soft_cfm>0</soft_cfm>
              <soft_erp>0.2</soft_erp>
              <kp>1e+13</kp>
              <kd>1</kd>
              <max_vel>0.01</max_vel>
              <min_depth>0</min_depth>
            </ode>
            <bullet>
              <split_impulse>1</split_impulse>
              <split_impulse_penetration_threshold>-0.01</split_impulse_penetration_threshold>
              <soft_cfm>0</soft_cfm>
              <soft_erp>0.2</soft_erp>
              <kp>1e+13</kp>
              <kd>1</kd>
            </bullet>
          </contact>
        </surface>
      </collision>
    </link>
    <link name='wheel_3'>
      <pose frame=''>0.1 -0.13 0 -1.5708 0 0</pose>
      <inertial>
        <pose frame=''>0 0 0 0 -0 0</pose>
        <mass>0.5</mass>
        <inertia>
          <ixx>0.01</ixx>
          <ixy>0</ixy>
          <ixz>0</ixz>
          <iyy>0.01</iyy>
          <iyz>0</iyz>
          <izz>0.01</izz>
        </inertia>
      </inertial>
      <gravity>1</gravity>
      <velocity_decay/>
      <self_collide>0</self_collide>
      <enable_wind>0</enable_wind>
      <kinematic>0</kinematic>
      <visual name='wheel_3_visual'>
        <pose frame=''>0 0 0 0 -0 0</pose>
        <geometry>
          <cylinder>
            <length>0.05</length>
            <radius>0.06</radius>
          </cylinder>
        </geometry>
        <material>
          <script>
            <name>Gazebo/Red</name>
            <uri>file://media/materials/scripts/gazebo.material</uri>
          </script>
          <shader type='pixel'/>
        </material>
        <transparency>0</transparency>
        <cast_shadows>1</cast_shadows>
      </visual>
      <collision name='wheel_3_collision'>
        <laser_retro>0</laser_retro>
        <max_contacts>10</max_contacts>
        <pose frame=''>0 0 0 0 -0 0</pose>
        <geometry>
          <cylinder>
            <radius>0.06</radius>
            <length>0.05</length>
          </cylinder>
        </geometry>
        <surface>
          <friction>
            <ode>
              <mu>1</mu>
              <mu2>1</mu2>
              <fdir1>0 0 0</fdir1>
              <slip1>0</slip1>
              <slip2>0</slip2>
            </ode>
            <torsional>
              <coefficient>1</coefficient>
              <patch_radius>0</patch_radius>
              <surface_radius>0</surface_radius>
              <use_patch_radius>1</use_patch_radius>
              <ode>
                <slip>0</slip>
              </ode>
            </torsional>
          </friction>
          <bounce>
            <restitution_coefficient>0</restitution_coefficient>
            <threshold>1e+06</threshold>
          </bounce>
          <contact>
            <collide_without_contact>0</collide_without_contact>
            <collide_without_contact_bitmask>1</collide_without_contact_bitmask>
            <collide_bitmask>1</collide_bitmask>
            <ode>
              <soft_cfm>0</soft_cfm>
              <soft_erp>0.2</soft_erp>
              <kp>1e+13</kp>
              <kd>1</kd>
              <max_vel>0.01</max_vel>
              <min_depth>0</min_depth>
            </ode>
            <bullet>
              <split_impulse>1</split_impulse>
              <split_impulse_penetration_threshold>-0.01</split_impulse_penetration_threshold>
              <soft_cfm>0</soft_cfm>
              <soft_erp>0.2</soft_erp>
              <kp>1e+13</kp>
              <kd>1</kd>
            </bullet>
          </contact>
        </surface>
      </collision>
    </link>
    <link name='wheel_4'>
      <pose frame=''>-0.099999 -0.13 0 -1.5708 0 0</pose>
      <inertial>
        <pose frame=''>0 0 0 0 -0 0</pose>
        <mass>0.5</mass>
        <inertia>
          <ixx>0.01</ixx>
          <ixy>0</ixy>
          <ixz>0</ixz>
          <iyy>0.01</iyy>
          <iyz>0</iyz>
          <izz>0.01</izz>
        </inertia>
      </inertial>
      <gravity>1</gravity>
      <velocity_decay/>
      <self_collide>0</self_collide>
      <enable_wind>0</enable_wind>
      <kinematic>0</kinematic>
      <visual name='wheel_4_visual'>
        <pose frame=''>0 0 0 0 -0 0</pose>
        <geometry>
          <cylinder>
            <length>0.05</length>
            <radius>0.06</radius>
          </cylinder>
        </geometry>
        <material>
          <script>
            <name>Gazebo/Black</name>
            <uri>file://media/materials/scripts/gazebo.material</uri>
          </script>
          <shader type='pixel'/>
        </material>
        <transparency>0</transparency>
        <cast_shadows>1</cast_shadows>
      </visual>
      <collision name='wheel_4_collision'>
        <laser_retro>0</laser_retro>
        <max_contacts>10</max_contacts>
        <pose frame=''>0 0 0 0 -0 0</pose>
        <geometry>
          <cylinder>
            <radius>0.06</radius>
            <length>0.05</length>
          </cylinder>
        </geometry>
        <surface>
          <friction>
            <ode>
              <mu>1</mu>
              <mu2>1</mu2>
              <fdir1>0 0 0</fdir1>
              <slip1>0</slip1>
              <slip2>0</slip2>
            </ode>
            <torsional>
              <coefficient>1</coefficient>
              <patch_radius>0</patch_radius>
              <surface_radius>0</surface_radius>
              <use_patch_radius>1</use_patch_radius>
              <ode>
                <slip>0</slip>
              </ode>
            </torsional>
          </friction>
          <bounce>
            <restitution_coefficient>0</restitution_coefficient>
            <threshold>1e+06</threshold>
          </bounce>
          <contact>
            <collide_without_contact>0</collide_without_contact>
            <collide_without_contact_bitmask>1</collide_without_contact_bitmask>
            <collide_bitmask>1</collide_bitmask>
            <ode>
              <soft_cfm>0</soft_cfm>
              <soft_erp>0.2</soft_erp>
              <kp>1e+13</kp>
              <kd>1</kd>
              <max_vel>0.01</max_vel>
              <min_depth>0</min_depth>
            </ode>
            <bullet>
              <split_impulse>1</split_impulse>
              <split_impulse_penetration_threshold>-0.01</split_impulse_penetration_threshold>
              <soft_cfm>0</soft_cfm>
              <soft_erp>0.2</soft_erp>
              <kp>1e+13</kp>
              <kd>1</kd>
            </bullet>
          </contact>
        </surface>
      </collision>
    </link>
    <joint name='base_to_wheel1' type='revolute'>
      <parent>dummy</parent>
      <child>wheel_1</child>
      <pose frame=''>0 -0 0 0 -0 0</pose>
      <axis>
        <xyz>0 0 1</xyz>
        <use_parent_model_frame>0</use_parent_model_frame>
        <limit>
          <lower>-1e+16</lower>
          <upper>1e+16</upper>
          <effort>-1</effort>
          <velocity>-1</velocity>
        </limit>
        <dynamics>
          <spring_reference>0</spring_reference>
          <spring_stiffness>0</spring_stiffness>
          <damping>0</damping>
          <friction>0</friction>
        </dynamics>
      </axis>
      <physics>
        <ode>
          <limit>
            <cfm>0</cfm>
            <erp>0.2</erp>
          </limit>
          <suspension>
            <cfm>0</cfm>
            <erp>0.2</erp>
          </suspension>
        </ode>
      </physics>
    </joint>
    <joint name='base_to_wheel2' type='revolute'>
      <parent>dummy</parent>
      <child>wheel_2</child>
      <pose frame=''>0 -0 0 0 -0 0</pose>
      <axis>
        <xyz>0 0 1</xyz>
        <use_parent_model_frame>0</use_parent_model_frame>
        <limit>
          <lower>-1e+16</lower>
          <upper>1e+16</upper>
          <effort>-1</effort>
          <velocity>-1</velocity>
        </limit>
        <dynamics>
          <spring_reference>0</spring_reference>
          <spring_stiffness>0</spring_stiffness>
          <damping>0</damping>
          <friction>0</friction>
        </dynamics>
      </axis>
      <physics>
        <ode>
          <limit>
            <cfm>0</cfm>
            <erp>0.2</erp>
          </limit>
          <suspension>
            <cfm>0</cfm>
            <erp>0.2</erp>
          </suspension>
        </ode>
      </physics>
    </joint>
    <joint name='base_to_wheel3' type='revolute'>
      <parent>dummy</parent>
      <child>wheel_3</child>
      <pose frame=''>0 0 0 0 -0 0</pose>
      <axis>
        <xyz>0 0 1</xyz>
        <use_parent_model_frame>0</use_parent_model_frame>
        <limit>
          <lower>-1e+16</lower>
          <upper>1e+16</upper>
          <effort>-1</effort>
          <velocity>-1</velocity>
        </limit>
        <dynamics>
          <spring_reference>0</spring_reference>
          <spring_stiffness>0</spring_stiffness>
          <damping>0</damping>
          <friction>0</friction>
        </dynamics>
      </axis>
      <physics>
        <ode>
          <limit>
            <cfm>0</cfm>
            <erp>0.2</erp>
          </limit>
          <suspension>
            <cfm>0</cfm>
            <erp>0.2</erp>
          </suspension>
        </ode>
      </physics>
    </joint>
    <joint name='base_to_wheel4' type='revolute'>
      <parent>dummy</parent>
      <child>wheel_4</child>
      <pose frame=''>0 0 0 0 -0 0</pose>
      <axis>
        <xyz>0 0 1</xyz>
        <use_parent_model_frame>0</use_parent_model_frame>
        <limit>
          <lower>-1e+16</lower>
          <upper>1e+16</upper>
          <effort>-1</effort>
          <velocity>-1</velocity>
        </limit>
        <dynamics>
          <spring_reference>0</spring_reference>
          <spring_stiffness>0</spring_stiffness>
          <damping>0</damping>
          <friction>0</friction>
        </dynamics>
      </axis>
      <physics>
        <ode>
          <limit>
            <cfm>0</cfm>
            <erp>0.2</erp>
          </limit>
          <suspension>
            <cfm>0</cfm>
            <erp>0.2</erp>
          </suspension>
        </ode>
      </physics>
    </joint>
    <static>0</static>
    <allow_auto_disable>1</allow_auto_disable>
    <plugin name='mecanum_controller' filename='libgazebo_ros_planar_move.so'>
      <alwaysOn>1</alwaysOn>
      <updateRate>100.0</updateRate>
      <robotNamespace>/</robotNamespace>
      <leftFrontJoint>base_to_wheel1</leftFrontJoint>
      <rightFrontJoint>base_to_wheel3</rightFrontJoint>
      <leftRearJoint>base_to_wheel2</leftRearJoint>
      <rightRearJoint>base_to_wheel4</rightRearJoint>
      <wheelSeparation>0.26</wheelSeparation>
      <wheelDiameter>0.12</wheelDiameter>
      <torque>2</torque>
      <commandTopic>/logger1/cmd_vel</commandTopic>
      <odometryTopic>odom</odometryTopic>
      <odometryFrame>odom</odometryFrame>
      <robotBaseFrame>dummy</robotBaseFrame>
      <broadcastTF>1</broadcastTF>
    </plugin>
  </model>
</sdf>
